{
 "cells": [
  {
   "cell_type": "code",
   "execution_count": 4,
   "metadata": {},
   "outputs": [],
   "source": [
    "import dtale\n",
    "import pandas as pd\n",
    "import numpy as np\n",
    "import matplotlib.pyplot as plt\n",
    "import re"
   ]
  },
  {
   "cell_type": "code",
   "execution_count": 5,
   "metadata": {},
   "outputs": [
    {
     "name": "stdout",
     "output_type": "stream",
     "text": [
      "Exception on /dtale/charts/_dash-update-component [POST]\n",
      "Traceback (most recent call last):\n",
      "  File \"/opt/homebrew/anaconda3/lib/python3.8/site-packages/flask/app.py\", line 2447, in wsgi_app\n",
      "    response = self.full_dispatch_request()\n",
      "  File \"/opt/homebrew/anaconda3/lib/python3.8/site-packages/flask/app.py\", line 1952, in full_dispatch_request\n",
      "    rv = self.handle_user_exception(e)\n",
      "  File \"/opt/homebrew/anaconda3/lib/python3.8/site-packages/flask/app.py\", line 1821, in handle_user_exception\n",
      "    reraise(exc_type, exc_value, tb)\n",
      "  File \"/opt/homebrew/anaconda3/lib/python3.8/site-packages/flask/_compat.py\", line 39, in reraise\n",
      "    raise value\n",
      "  File \"/opt/homebrew/anaconda3/lib/python3.8/site-packages/flask/app.py\", line 1950, in full_dispatch_request\n",
      "    rv = self.dispatch_request()\n",
      "  File \"/opt/homebrew/anaconda3/lib/python3.8/site-packages/flask/app.py\", line 1936, in dispatch_request\n",
      "    return self.view_functions[rule.endpoint](**req.view_args)\n",
      "  File \"/opt/homebrew/anaconda3/lib/python3.8/site-packages/dash/dash.py\", line 1096, in dispatch\n",
      "    response.set_data(func(*args, outputs_list=outputs_list))\n",
      "  File \"/opt/homebrew/anaconda3/lib/python3.8/site-packages/dash/dash.py\", line 1017, in add_context\n",
      "    output_value = func(*args, **kwargs)  # %% callback invoked %%\n",
      "  File \"/opt/homebrew/anaconda3/lib/python3.8/site-packages/dtale/dash_application/saved_charts.py\", line 202, in load_saved_chart\n",
      "    return dict(display=\"block\"), charts, config, build_saved_header(config)\n",
      "  File \"/opt/homebrew/anaconda3/lib/python3.8/site-packages/dtale/dash_application/saved_charts.py\", line 114, in build_saved_header\n",
      "    (\"Selected Groups\", \", \".join(make_list(config[\"groups\"])))\n",
      "KeyError: 'groups'\n",
      "Exception on /dtale/charts/_dash-update-component [POST]\n",
      "Traceback (most recent call last):\n",
      "  File \"/opt/homebrew/anaconda3/lib/python3.8/site-packages/flask/app.py\", line 2447, in wsgi_app\n",
      "    response = self.full_dispatch_request()\n",
      "  File \"/opt/homebrew/anaconda3/lib/python3.8/site-packages/flask/app.py\", line 1952, in full_dispatch_request\n",
      "    rv = self.handle_user_exception(e)\n",
      "  File \"/opt/homebrew/anaconda3/lib/python3.8/site-packages/flask/app.py\", line 1821, in handle_user_exception\n",
      "    reraise(exc_type, exc_value, tb)\n",
      "  File \"/opt/homebrew/anaconda3/lib/python3.8/site-packages/flask/_compat.py\", line 39, in reraise\n",
      "    raise value\n",
      "  File \"/opt/homebrew/anaconda3/lib/python3.8/site-packages/flask/app.py\", line 1950, in full_dispatch_request\n",
      "    rv = self.dispatch_request()\n",
      "  File \"/opt/homebrew/anaconda3/lib/python3.8/site-packages/flask/app.py\", line 1936, in dispatch_request\n",
      "    return self.view_functions[rule.endpoint](**req.view_args)\n",
      "  File \"/opt/homebrew/anaconda3/lib/python3.8/site-packages/dash/dash.py\", line 1096, in dispatch\n",
      "    response.set_data(func(*args, outputs_list=outputs_list))\n",
      "  File \"/opt/homebrew/anaconda3/lib/python3.8/site-packages/dash/dash.py\", line 1017, in add_context\n",
      "    output_value = func(*args, **kwargs)  # %% callback invoked %%\n",
      "  File \"/opt/homebrew/anaconda3/lib/python3.8/site-packages/dtale/dash_application/saved_charts.py\", line 202, in load_saved_chart\n",
      "    return dict(display=\"block\"), charts, config, build_saved_header(config)\n",
      "  File \"/opt/homebrew/anaconda3/lib/python3.8/site-packages/dtale/dash_application/saved_charts.py\", line 114, in build_saved_header\n",
      "    (\"Selected Groups\", \", \".join(make_list(config[\"groups\"])))\n",
      "KeyError: 'groups'\n"
     ]
    },
    {
     "name": "stderr",
     "output_type": "stream",
     "text": [
      "2021-08-21 14:24:47,877 - ERROR    - Exception on /dtale/charts/_dash-update-component [POST]\n",
      "Traceback (most recent call last):\n",
      "  File \"/opt/homebrew/anaconda3/lib/python3.8/site-packages/flask/app.py\", line 2447, in wsgi_app\n",
      "    response = self.full_dispatch_request()\n",
      "  File \"/opt/homebrew/anaconda3/lib/python3.8/site-packages/flask/app.py\", line 1952, in full_dispatch_request\n",
      "    rv = self.handle_user_exception(e)\n",
      "  File \"/opt/homebrew/anaconda3/lib/python3.8/site-packages/flask/app.py\", line 1821, in handle_user_exception\n",
      "    reraise(exc_type, exc_value, tb)\n",
      "  File \"/opt/homebrew/anaconda3/lib/python3.8/site-packages/flask/_compat.py\", line 39, in reraise\n",
      "    raise value\n",
      "  File \"/opt/homebrew/anaconda3/lib/python3.8/site-packages/flask/app.py\", line 1950, in full_dispatch_request\n",
      "    rv = self.dispatch_request()\n",
      "  File \"/opt/homebrew/anaconda3/lib/python3.8/site-packages/flask/app.py\", line 1936, in dispatch_request\n",
      "    return self.view_functions[rule.endpoint](**req.view_args)\n",
      "  File \"/opt/homebrew/anaconda3/lib/python3.8/site-packages/dash/dash.py\", line 1096, in dispatch\n",
      "    response.set_data(func(*args, outputs_list=outputs_list))\n",
      "  File \"/opt/homebrew/anaconda3/lib/python3.8/site-packages/dash/dash.py\", line 1017, in add_context\n",
      "    output_value = func(*args, **kwargs)  # %% callback invoked %%\n",
      "  File \"/opt/homebrew/anaconda3/lib/python3.8/site-packages/dtale/dash_application/saved_charts.py\", line 202, in load_saved_chart\n",
      "    return dict(display=\"block\"), charts, config, build_saved_header(config)\n",
      "  File \"/opt/homebrew/anaconda3/lib/python3.8/site-packages/dtale/dash_application/saved_charts.py\", line 114, in build_saved_header\n",
      "    (\"Selected Groups\", \", \".join(make_list(config[\"groups\"])))\n",
      "KeyError: 'groups'\n"
     ]
    },
    {
     "name": "stdout",
     "output_type": "stream",
     "text": [
      "Exception on /dtale/charts/_dash-update-component [POST]\n",
      "Traceback (most recent call last):\n",
      "  File \"/opt/homebrew/anaconda3/lib/python3.8/site-packages/flask/app.py\", line 2447, in wsgi_app\n",
      "    response = self.full_dispatch_request()\n",
      "  File \"/opt/homebrew/anaconda3/lib/python3.8/site-packages/flask/app.py\", line 1952, in full_dispatch_request\n",
      "    rv = self.handle_user_exception(e)\n",
      "  File \"/opt/homebrew/anaconda3/lib/python3.8/site-packages/flask/app.py\", line 1821, in handle_user_exception\n",
      "    reraise(exc_type, exc_value, tb)\n",
      "  File \"/opt/homebrew/anaconda3/lib/python3.8/site-packages/flask/_compat.py\", line 39, in reraise\n",
      "    raise value\n",
      "  File \"/opt/homebrew/anaconda3/lib/python3.8/site-packages/flask/app.py\", line 1950, in full_dispatch_request\n",
      "    rv = self.dispatch_request()\n",
      "  File \"/opt/homebrew/anaconda3/lib/python3.8/site-packages/flask/app.py\", line 1936, in dispatch_request\n",
      "    return self.view_functions[rule.endpoint](**req.view_args)\n",
      "  File \"/opt/homebrew/anaconda3/lib/python3.8/site-packages/dash/dash.py\", line 1096, in dispatch\n",
      "    response.set_data(func(*args, outputs_list=outputs_list))\n",
      "  File \"/opt/homebrew/anaconda3/lib/python3.8/site-packages/dash/dash.py\", line 1017, in add_context\n",
      "    output_value = func(*args, **kwargs)  # %% callback invoked %%\n",
      "  File \"/opt/homebrew/anaconda3/lib/python3.8/site-packages/dtale/dash_application/saved_charts.py\", line 202, in load_saved_chart\n",
      "    return dict(display=\"block\"), charts, config, build_saved_header(config)\n",
      "  File \"/opt/homebrew/anaconda3/lib/python3.8/site-packages/dtale/dash_application/saved_charts.py\", line 114, in build_saved_header\n",
      "    (\"Selected Groups\", \", \".join(make_list(config[\"groups\"])))\n",
      "KeyError: 'groups'\n",
      "Exception on /dtale/charts/_dash-update-component [POST]\n",
      "Traceback (most recent call last):\n",
      "  File \"/opt/homebrew/anaconda3/lib/python3.8/site-packages/flask/app.py\", line 2447, in wsgi_app\n",
      "    response = self.full_dispatch_request()\n",
      "  File \"/opt/homebrew/anaconda3/lib/python3.8/site-packages/flask/app.py\", line 1952, in full_dispatch_request\n",
      "    rv = self.handle_user_exception(e)\n",
      "  File \"/opt/homebrew/anaconda3/lib/python3.8/site-packages/flask/app.py\", line 1821, in handle_user_exception\n",
      "    reraise(exc_type, exc_value, tb)\n",
      "  File \"/opt/homebrew/anaconda3/lib/python3.8/site-packages/flask/_compat.py\", line 39, in reraise\n",
      "    raise value\n",
      "  File \"/opt/homebrew/anaconda3/lib/python3.8/site-packages/flask/app.py\", line 1950, in full_dispatch_request\n",
      "    rv = self.dispatch_request()\n",
      "  File \"/opt/homebrew/anaconda3/lib/python3.8/site-packages/flask/app.py\", line 1936, in dispatch_request\n",
      "    return self.view_functions[rule.endpoint](**req.view_args)\n",
      "  File \"/opt/homebrew/anaconda3/lib/python3.8/site-packages/dash/dash.py\", line 1096, in dispatch\n",
      "    response.set_data(func(*args, outputs_list=outputs_list))\n",
      "  File \"/opt/homebrew/anaconda3/lib/python3.8/site-packages/dash/dash.py\", line 1017, in add_context\n",
      "    output_value = func(*args, **kwargs)  # %% callback invoked %%\n",
      "  File \"/opt/homebrew/anaconda3/lib/python3.8/site-packages/dtale/dash_application/saved_charts.py\", line 202, in load_saved_chart\n",
      "    return dict(display=\"block\"), charts, config, build_saved_header(config)\n",
      "  File \"/opt/homebrew/anaconda3/lib/python3.8/site-packages/dtale/dash_application/saved_charts.py\", line 114, in build_saved_header\n",
      "    (\"Selected Groups\", \", \".join(make_list(config[\"groups\"])))\n",
      "KeyError: 'groups'\n"
     ]
    },
    {
     "name": "stderr",
     "output_type": "stream",
     "text": [
      "2021-08-21 14:25:00,521 - ERROR    - Exception on /dtale/charts/_dash-update-component [POST]\n",
      "Traceback (most recent call last):\n",
      "  File \"/opt/homebrew/anaconda3/lib/python3.8/site-packages/flask/app.py\", line 2447, in wsgi_app\n",
      "    response = self.full_dispatch_request()\n",
      "  File \"/opt/homebrew/anaconda3/lib/python3.8/site-packages/flask/app.py\", line 1952, in full_dispatch_request\n",
      "    rv = self.handle_user_exception(e)\n",
      "  File \"/opt/homebrew/anaconda3/lib/python3.8/site-packages/flask/app.py\", line 1821, in handle_user_exception\n",
      "    reraise(exc_type, exc_value, tb)\n",
      "  File \"/opt/homebrew/anaconda3/lib/python3.8/site-packages/flask/_compat.py\", line 39, in reraise\n",
      "    raise value\n",
      "  File \"/opt/homebrew/anaconda3/lib/python3.8/site-packages/flask/app.py\", line 1950, in full_dispatch_request\n",
      "    rv = self.dispatch_request()\n",
      "  File \"/opt/homebrew/anaconda3/lib/python3.8/site-packages/flask/app.py\", line 1936, in dispatch_request\n",
      "    return self.view_functions[rule.endpoint](**req.view_args)\n",
      "  File \"/opt/homebrew/anaconda3/lib/python3.8/site-packages/dash/dash.py\", line 1096, in dispatch\n",
      "    response.set_data(func(*args, outputs_list=outputs_list))\n",
      "  File \"/opt/homebrew/anaconda3/lib/python3.8/site-packages/dash/dash.py\", line 1017, in add_context\n",
      "    output_value = func(*args, **kwargs)  # %% callback invoked %%\n",
      "  File \"/opt/homebrew/anaconda3/lib/python3.8/site-packages/dtale/dash_application/saved_charts.py\", line 202, in load_saved_chart\n",
      "    return dict(display=\"block\"), charts, config, build_saved_header(config)\n",
      "  File \"/opt/homebrew/anaconda3/lib/python3.8/site-packages/dtale/dash_application/saved_charts.py\", line 114, in build_saved_header\n",
      "    (\"Selected Groups\", \", \".join(make_list(config[\"groups\"])))\n",
      "KeyError: 'groups'\n"
     ]
    },
    {
     "name": "stdout",
     "output_type": "stream",
     "text": [
      "Exception on /dtale/charts/_dash-update-component [POST]\n",
      "Traceback (most recent call last):\n",
      "  File \"/opt/homebrew/anaconda3/lib/python3.8/site-packages/flask/app.py\", line 2447, in wsgi_app\n",
      "    response = self.full_dispatch_request()\n",
      "  File \"/opt/homebrew/anaconda3/lib/python3.8/site-packages/flask/app.py\", line 1952, in full_dispatch_request\n",
      "    rv = self.handle_user_exception(e)\n",
      "  File \"/opt/homebrew/anaconda3/lib/python3.8/site-packages/flask/app.py\", line 1821, in handle_user_exception\n",
      "    reraise(exc_type, exc_value, tb)\n",
      "  File \"/opt/homebrew/anaconda3/lib/python3.8/site-packages/flask/_compat.py\", line 39, in reraise\n",
      "    raise value\n",
      "  File \"/opt/homebrew/anaconda3/lib/python3.8/site-packages/flask/app.py\", line 1950, in full_dispatch_request\n",
      "    rv = self.dispatch_request()\n",
      "  File \"/opt/homebrew/anaconda3/lib/python3.8/site-packages/flask/app.py\", line 1936, in dispatch_request\n",
      "    return self.view_functions[rule.endpoint](**req.view_args)\n",
      "  File \"/opt/homebrew/anaconda3/lib/python3.8/site-packages/dash/dash.py\", line 1096, in dispatch\n",
      "    response.set_data(func(*args, outputs_list=outputs_list))\n",
      "  File \"/opt/homebrew/anaconda3/lib/python3.8/site-packages/dash/dash.py\", line 1017, in add_context\n",
      "    output_value = func(*args, **kwargs)  # %% callback invoked %%\n",
      "  File \"/opt/homebrew/anaconda3/lib/python3.8/site-packages/dtale/dash_application/views.py\", line 1112, in group_values\n",
      "    group_vals = build_group_val_options(group_vals, group_cols)\n",
      "  File \"/opt/homebrew/anaconda3/lib/python3.8/site-packages/dtale/dash_application/layout/layout.py\", line 1053, in build_group_val_options\n",
      "    group_vals = find_group_vals(df, group_cols)\n",
      "  File \"/opt/homebrew/anaconda3/lib/python3.8/site-packages/dtale/charts/utils.py\", line 1000, in find_group_vals\n",
      "    group_vals, _ = retrieve_chart_data(df, group_cols)\n",
      "  File \"/opt/homebrew/anaconda3/lib/python3.8/site-packages/dtale/charts/utils.py\", line 350, in retrieve_chart_data\n",
      "    all_data = pd.concat(all_data, axis=1)\n",
      "  File \"/opt/homebrew/anaconda3/lib/python3.8/site-packages/pandas/core/reshape/concat.py\", line 274, in concat\n",
      "    op = _Concatenator(\n",
      "  File \"/opt/homebrew/anaconda3/lib/python3.8/site-packages/pandas/core/reshape/concat.py\", line 331, in __init__\n",
      "    raise ValueError(\"No objects to concatenate\")\n",
      "ValueError: No objects to concatenate\n",
      "Exception on /dtale/charts/_dash-update-component [POST]\n",
      "Traceback (most recent call last):\n",
      "  File \"/opt/homebrew/anaconda3/lib/python3.8/site-packages/flask/app.py\", line 2447, in wsgi_app\n",
      "    response = self.full_dispatch_request()\n",
      "  File \"/opt/homebrew/anaconda3/lib/python3.8/site-packages/flask/app.py\", line 1952, in full_dispatch_request\n",
      "    rv = self.handle_user_exception(e)\n",
      "  File \"/opt/homebrew/anaconda3/lib/python3.8/site-packages/flask/app.py\", line 1821, in handle_user_exception\n",
      "    reraise(exc_type, exc_value, tb)\n",
      "  File \"/opt/homebrew/anaconda3/lib/python3.8/site-packages/flask/_compat.py\", line 39, in reraise\n",
      "    raise value\n",
      "  File \"/opt/homebrew/anaconda3/lib/python3.8/site-packages/flask/app.py\", line 1950, in full_dispatch_request\n",
      "    rv = self.dispatch_request()\n",
      "  File \"/opt/homebrew/anaconda3/lib/python3.8/site-packages/flask/app.py\", line 1936, in dispatch_request\n",
      "    return self.view_functions[rule.endpoint](**req.view_args)\n",
      "  File \"/opt/homebrew/anaconda3/lib/python3.8/site-packages/dash/dash.py\", line 1096, in dispatch\n",
      "    response.set_data(func(*args, outputs_list=outputs_list))\n",
      "  File \"/opt/homebrew/anaconda3/lib/python3.8/site-packages/dash/dash.py\", line 1017, in add_context\n",
      "    output_value = func(*args, **kwargs)  # %% callback invoked %%\n",
      "  File \"/opt/homebrew/anaconda3/lib/python3.8/site-packages/dtale/dash_application/views.py\", line 1112, in group_values\n",
      "    group_vals = build_group_val_options(group_vals, group_cols)\n",
      "  File \"/opt/homebrew/anaconda3/lib/python3.8/site-packages/dtale/dash_application/layout/layout.py\", line 1053, in build_group_val_options\n",
      "    group_vals = find_group_vals(df, group_cols)\n",
      "  File \"/opt/homebrew/anaconda3/lib/python3.8/site-packages/dtale/charts/utils.py\", line 1000, in find_group_vals\n",
      "    group_vals, _ = retrieve_chart_data(df, group_cols)\n",
      "  File \"/opt/homebrew/anaconda3/lib/python3.8/site-packages/dtale/charts/utils.py\", line 350, in retrieve_chart_data\n",
      "    all_data = pd.concat(all_data, axis=1)\n",
      "  File \"/opt/homebrew/anaconda3/lib/python3.8/site-packages/pandas/core/reshape/concat.py\", line 274, in concat\n",
      "    op = _Concatenator(\n",
      "  File \"/opt/homebrew/anaconda3/lib/python3.8/site-packages/pandas/core/reshape/concat.py\", line 331, in __init__\n",
      "    raise ValueError(\"No objects to concatenate\")\n",
      "ValueError: No objects to concatenate\n"
     ]
    },
    {
     "name": "stderr",
     "output_type": "stream",
     "text": [
      "2021-08-21 14:25:37,837 - ERROR    - Exception on /dtale/charts/_dash-update-component [POST]\n",
      "Traceback (most recent call last):\n",
      "  File \"/opt/homebrew/anaconda3/lib/python3.8/site-packages/flask/app.py\", line 2447, in wsgi_app\n",
      "    response = self.full_dispatch_request()\n",
      "  File \"/opt/homebrew/anaconda3/lib/python3.8/site-packages/flask/app.py\", line 1952, in full_dispatch_request\n",
      "    rv = self.handle_user_exception(e)\n",
      "  File \"/opt/homebrew/anaconda3/lib/python3.8/site-packages/flask/app.py\", line 1821, in handle_user_exception\n",
      "    reraise(exc_type, exc_value, tb)\n",
      "  File \"/opt/homebrew/anaconda3/lib/python3.8/site-packages/flask/_compat.py\", line 39, in reraise\n",
      "    raise value\n",
      "  File \"/opt/homebrew/anaconda3/lib/python3.8/site-packages/flask/app.py\", line 1950, in full_dispatch_request\n",
      "    rv = self.dispatch_request()\n",
      "  File \"/opt/homebrew/anaconda3/lib/python3.8/site-packages/flask/app.py\", line 1936, in dispatch_request\n",
      "    return self.view_functions[rule.endpoint](**req.view_args)\n",
      "  File \"/opt/homebrew/anaconda3/lib/python3.8/site-packages/dash/dash.py\", line 1096, in dispatch\n",
      "    response.set_data(func(*args, outputs_list=outputs_list))\n",
      "  File \"/opt/homebrew/anaconda3/lib/python3.8/site-packages/dash/dash.py\", line 1017, in add_context\n",
      "    output_value = func(*args, **kwargs)  # %% callback invoked %%\n",
      "  File \"/opt/homebrew/anaconda3/lib/python3.8/site-packages/dtale/dash_application/views.py\", line 1112, in group_values\n",
      "    group_vals = build_group_val_options(group_vals, group_cols)\n",
      "  File \"/opt/homebrew/anaconda3/lib/python3.8/site-packages/dtale/dash_application/layout/layout.py\", line 1053, in build_group_val_options\n",
      "    group_vals = find_group_vals(df, group_cols)\n",
      "  File \"/opt/homebrew/anaconda3/lib/python3.8/site-packages/dtale/charts/utils.py\", line 1000, in find_group_vals\n",
      "    group_vals, _ = retrieve_chart_data(df, group_cols)\n",
      "  File \"/opt/homebrew/anaconda3/lib/python3.8/site-packages/dtale/charts/utils.py\", line 350, in retrieve_chart_data\n",
      "    all_data = pd.concat(all_data, axis=1)\n",
      "  File \"/opt/homebrew/anaconda3/lib/python3.8/site-packages/pandas/core/reshape/concat.py\", line 274, in concat\n",
      "    op = _Concatenator(\n",
      "  File \"/opt/homebrew/anaconda3/lib/python3.8/site-packages/pandas/core/reshape/concat.py\", line 331, in __init__\n",
      "    raise ValueError(\"No objects to concatenate\")\n",
      "ValueError: No objects to concatenate\n"
     ]
    },
    {
     "name": "stdout",
     "output_type": "stream",
     "text": [
      "Exception on /dtale/charts/_dash-update-component [POST]\n",
      "Traceback (most recent call last):\n",
      "  File \"/opt/homebrew/anaconda3/lib/python3.8/site-packages/flask/app.py\", line 2447, in wsgi_app\n",
      "    response = self.full_dispatch_request()\n",
      "  File \"/opt/homebrew/anaconda3/lib/python3.8/site-packages/flask/app.py\", line 1952, in full_dispatch_request\n",
      "    rv = self.handle_user_exception(e)\n",
      "  File \"/opt/homebrew/anaconda3/lib/python3.8/site-packages/flask/app.py\", line 1821, in handle_user_exception\n",
      "    reraise(exc_type, exc_value, tb)\n",
      "  File \"/opt/homebrew/anaconda3/lib/python3.8/site-packages/flask/_compat.py\", line 39, in reraise\n",
      "    raise value\n",
      "  File \"/opt/homebrew/anaconda3/lib/python3.8/site-packages/flask/app.py\", line 1950, in full_dispatch_request\n",
      "    rv = self.dispatch_request()\n",
      "  File \"/opt/homebrew/anaconda3/lib/python3.8/site-packages/flask/app.py\", line 1936, in dispatch_request\n",
      "    return self.view_functions[rule.endpoint](**req.view_args)\n",
      "  File \"/opt/homebrew/anaconda3/lib/python3.8/site-packages/dash/dash.py\", line 1096, in dispatch\n",
      "    response.set_data(func(*args, outputs_list=outputs_list))\n",
      "  File \"/opt/homebrew/anaconda3/lib/python3.8/site-packages/dash/dash.py\", line 1017, in add_context\n",
      "    output_value = func(*args, **kwargs)  # %% callback invoked %%\n",
      "  File \"/opt/homebrew/anaconda3/lib/python3.8/site-packages/dtale/dash_application/views.py\", line 1112, in group_values\n",
      "    group_vals = build_group_val_options(group_vals, group_cols)\n",
      "  File \"/opt/homebrew/anaconda3/lib/python3.8/site-packages/dtale/dash_application/layout/layout.py\", line 1053, in build_group_val_options\n",
      "    group_vals = find_group_vals(df, group_cols)\n",
      "  File \"/opt/homebrew/anaconda3/lib/python3.8/site-packages/dtale/charts/utils.py\", line 1000, in find_group_vals\n",
      "    group_vals, _ = retrieve_chart_data(df, group_cols)\n",
      "  File \"/opt/homebrew/anaconda3/lib/python3.8/site-packages/dtale/charts/utils.py\", line 350, in retrieve_chart_data\n",
      "    all_data = pd.concat(all_data, axis=1)\n",
      "  File \"/opt/homebrew/anaconda3/lib/python3.8/site-packages/pandas/core/reshape/concat.py\", line 274, in concat\n",
      "    op = _Concatenator(\n",
      "  File \"/opt/homebrew/anaconda3/lib/python3.8/site-packages/pandas/core/reshape/concat.py\", line 331, in __init__\n",
      "    raise ValueError(\"No objects to concatenate\")\n",
      "ValueError: No objects to concatenate\n",
      "Exception on /dtale/charts/_dash-update-component [POST]\n",
      "Traceback (most recent call last):\n",
      "  File \"/opt/homebrew/anaconda3/lib/python3.8/site-packages/flask/app.py\", line 2447, in wsgi_app\n",
      "    response = self.full_dispatch_request()\n",
      "  File \"/opt/homebrew/anaconda3/lib/python3.8/site-packages/flask/app.py\", line 1952, in full_dispatch_request\n",
      "    rv = self.handle_user_exception(e)\n",
      "  File \"/opt/homebrew/anaconda3/lib/python3.8/site-packages/flask/app.py\", line 1821, in handle_user_exception\n",
      "    reraise(exc_type, exc_value, tb)\n",
      "  File \"/opt/homebrew/anaconda3/lib/python3.8/site-packages/flask/_compat.py\", line 39, in reraise\n",
      "    raise value\n",
      "  File \"/opt/homebrew/anaconda3/lib/python3.8/site-packages/flask/app.py\", line 1950, in full_dispatch_request\n",
      "    rv = self.dispatch_request()\n",
      "  File \"/opt/homebrew/anaconda3/lib/python3.8/site-packages/flask/app.py\", line 1936, in dispatch_request\n",
      "    return self.view_functions[rule.endpoint](**req.view_args)\n",
      "  File \"/opt/homebrew/anaconda3/lib/python3.8/site-packages/dash/dash.py\", line 1096, in dispatch\n",
      "    response.set_data(func(*args, outputs_list=outputs_list))\n",
      "  File \"/opt/homebrew/anaconda3/lib/python3.8/site-packages/dash/dash.py\", line 1017, in add_context\n",
      "    output_value = func(*args, **kwargs)  # %% callback invoked %%\n",
      "  File \"/opt/homebrew/anaconda3/lib/python3.8/site-packages/dtale/dash_application/views.py\", line 1112, in group_values\n",
      "    group_vals = build_group_val_options(group_vals, group_cols)\n",
      "  File \"/opt/homebrew/anaconda3/lib/python3.8/site-packages/dtale/dash_application/layout/layout.py\", line 1053, in build_group_val_options\n",
      "    group_vals = find_group_vals(df, group_cols)\n",
      "  File \"/opt/homebrew/anaconda3/lib/python3.8/site-packages/dtale/charts/utils.py\", line 1000, in find_group_vals\n",
      "    group_vals, _ = retrieve_chart_data(df, group_cols)\n",
      "  File \"/opt/homebrew/anaconda3/lib/python3.8/site-packages/dtale/charts/utils.py\", line 350, in retrieve_chart_data\n",
      "    all_data = pd.concat(all_data, axis=1)\n",
      "  File \"/opt/homebrew/anaconda3/lib/python3.8/site-packages/pandas/core/reshape/concat.py\", line 274, in concat\n",
      "    op = _Concatenator(\n",
      "  File \"/opt/homebrew/anaconda3/lib/python3.8/site-packages/pandas/core/reshape/concat.py\", line 331, in __init__\n",
      "    raise ValueError(\"No objects to concatenate\")\n",
      "ValueError: No objects to concatenate\n"
     ]
    },
    {
     "name": "stderr",
     "output_type": "stream",
     "text": [
      "2021-08-21 14:29:28,872 - ERROR    - Exception on /dtale/charts/_dash-update-component [POST]\n",
      "Traceback (most recent call last):\n",
      "  File \"/opt/homebrew/anaconda3/lib/python3.8/site-packages/flask/app.py\", line 2447, in wsgi_app\n",
      "    response = self.full_dispatch_request()\n",
      "  File \"/opt/homebrew/anaconda3/lib/python3.8/site-packages/flask/app.py\", line 1952, in full_dispatch_request\n",
      "    rv = self.handle_user_exception(e)\n",
      "  File \"/opt/homebrew/anaconda3/lib/python3.8/site-packages/flask/app.py\", line 1821, in handle_user_exception\n",
      "    reraise(exc_type, exc_value, tb)\n",
      "  File \"/opt/homebrew/anaconda3/lib/python3.8/site-packages/flask/_compat.py\", line 39, in reraise\n",
      "    raise value\n",
      "  File \"/opt/homebrew/anaconda3/lib/python3.8/site-packages/flask/app.py\", line 1950, in full_dispatch_request\n",
      "    rv = self.dispatch_request()\n",
      "  File \"/opt/homebrew/anaconda3/lib/python3.8/site-packages/flask/app.py\", line 1936, in dispatch_request\n",
      "    return self.view_functions[rule.endpoint](**req.view_args)\n",
      "  File \"/opt/homebrew/anaconda3/lib/python3.8/site-packages/dash/dash.py\", line 1096, in dispatch\n",
      "    response.set_data(func(*args, outputs_list=outputs_list))\n",
      "  File \"/opt/homebrew/anaconda3/lib/python3.8/site-packages/dash/dash.py\", line 1017, in add_context\n",
      "    output_value = func(*args, **kwargs)  # %% callback invoked %%\n",
      "  File \"/opt/homebrew/anaconda3/lib/python3.8/site-packages/dtale/dash_application/views.py\", line 1112, in group_values\n",
      "    group_vals = build_group_val_options(group_vals, group_cols)\n",
      "  File \"/opt/homebrew/anaconda3/lib/python3.8/site-packages/dtale/dash_application/layout/layout.py\", line 1053, in build_group_val_options\n",
      "    group_vals = find_group_vals(df, group_cols)\n",
      "  File \"/opt/homebrew/anaconda3/lib/python3.8/site-packages/dtale/charts/utils.py\", line 1000, in find_group_vals\n",
      "    group_vals, _ = retrieve_chart_data(df, group_cols)\n",
      "  File \"/opt/homebrew/anaconda3/lib/python3.8/site-packages/dtale/charts/utils.py\", line 350, in retrieve_chart_data\n",
      "    all_data = pd.concat(all_data, axis=1)\n",
      "  File \"/opt/homebrew/anaconda3/lib/python3.8/site-packages/pandas/core/reshape/concat.py\", line 274, in concat\n",
      "    op = _Concatenator(\n",
      "  File \"/opt/homebrew/anaconda3/lib/python3.8/site-packages/pandas/core/reshape/concat.py\", line 331, in __init__\n",
      "    raise ValueError(\"No objects to concatenate\")\n",
      "ValueError: No objects to concatenate\n"
     ]
    },
    {
     "name": "stdout",
     "output_type": "stream",
     "text": [
      "Exception on /dtale/charts/_dash-update-component [POST]\n",
      "Traceback (most recent call last):\n",
      "  File \"/opt/homebrew/anaconda3/lib/python3.8/site-packages/flask/app.py\", line 2447, in wsgi_app\n",
      "    response = self.full_dispatch_request()\n",
      "  File \"/opt/homebrew/anaconda3/lib/python3.8/site-packages/flask/app.py\", line 1952, in full_dispatch_request\n",
      "    rv = self.handle_user_exception(e)\n",
      "  File \"/opt/homebrew/anaconda3/lib/python3.8/site-packages/flask/app.py\", line 1821, in handle_user_exception\n",
      "    reraise(exc_type, exc_value, tb)\n",
      "  File \"/opt/homebrew/anaconda3/lib/python3.8/site-packages/flask/_compat.py\", line 39, in reraise\n",
      "    raise value\n",
      "  File \"/opt/homebrew/anaconda3/lib/python3.8/site-packages/flask/app.py\", line 1950, in full_dispatch_request\n",
      "    rv = self.dispatch_request()\n",
      "  File \"/opt/homebrew/anaconda3/lib/python3.8/site-packages/flask/app.py\", line 1936, in dispatch_request\n",
      "    return self.view_functions[rule.endpoint](**req.view_args)\n",
      "  File \"/opt/homebrew/anaconda3/lib/python3.8/site-packages/dash/dash.py\", line 1096, in dispatch\n",
      "    response.set_data(func(*args, outputs_list=outputs_list))\n",
      "  File \"/opt/homebrew/anaconda3/lib/python3.8/site-packages/dash/dash.py\", line 1017, in add_context\n",
      "    output_value = func(*args, **kwargs)  # %% callback invoked %%\n",
      "  File \"/opt/homebrew/anaconda3/lib/python3.8/site-packages/dtale/dash_application/views.py\", line 1112, in group_values\n",
      "    group_vals = build_group_val_options(group_vals, group_cols)\n",
      "  File \"/opt/homebrew/anaconda3/lib/python3.8/site-packages/dtale/dash_application/layout/layout.py\", line 1053, in build_group_val_options\n",
      "    group_vals = find_group_vals(df, group_cols)\n",
      "  File \"/opt/homebrew/anaconda3/lib/python3.8/site-packages/dtale/charts/utils.py\", line 1000, in find_group_vals\n",
      "    group_vals, _ = retrieve_chart_data(df, group_cols)\n",
      "  File \"/opt/homebrew/anaconda3/lib/python3.8/site-packages/dtale/charts/utils.py\", line 350, in retrieve_chart_data\n",
      "    all_data = pd.concat(all_data, axis=1)\n",
      "  File \"/opt/homebrew/anaconda3/lib/python3.8/site-packages/pandas/core/reshape/concat.py\", line 274, in concat\n",
      "    op = _Concatenator(\n",
      "  File \"/opt/homebrew/anaconda3/lib/python3.8/site-packages/pandas/core/reshape/concat.py\", line 331, in __init__\n",
      "    raise ValueError(\"No objects to concatenate\")\n",
      "ValueError: No objects to concatenate\n",
      "Exception on /dtale/charts/_dash-update-component [POST]\n",
      "Traceback (most recent call last):\n",
      "  File \"/opt/homebrew/anaconda3/lib/python3.8/site-packages/flask/app.py\", line 2447, in wsgi_app\n",
      "    response = self.full_dispatch_request()\n",
      "  File \"/opt/homebrew/anaconda3/lib/python3.8/site-packages/flask/app.py\", line 1952, in full_dispatch_request\n",
      "    rv = self.handle_user_exception(e)\n",
      "  File \"/opt/homebrew/anaconda3/lib/python3.8/site-packages/flask/app.py\", line 1821, in handle_user_exception\n",
      "    reraise(exc_type, exc_value, tb)\n",
      "  File \"/opt/homebrew/anaconda3/lib/python3.8/site-packages/flask/_compat.py\", line 39, in reraise\n",
      "    raise value\n",
      "  File \"/opt/homebrew/anaconda3/lib/python3.8/site-packages/flask/app.py\", line 1950, in full_dispatch_request\n",
      "    rv = self.dispatch_request()\n",
      "  File \"/opt/homebrew/anaconda3/lib/python3.8/site-packages/flask/app.py\", line 1936, in dispatch_request\n",
      "    return self.view_functions[rule.endpoint](**req.view_args)\n",
      "  File \"/opt/homebrew/anaconda3/lib/python3.8/site-packages/dash/dash.py\", line 1096, in dispatch\n",
      "    response.set_data(func(*args, outputs_list=outputs_list))\n",
      "  File \"/opt/homebrew/anaconda3/lib/python3.8/site-packages/dash/dash.py\", line 1017, in add_context\n",
      "    output_value = func(*args, **kwargs)  # %% callback invoked %%\n",
      "  File \"/opt/homebrew/anaconda3/lib/python3.8/site-packages/dtale/dash_application/views.py\", line 1112, in group_values\n",
      "    group_vals = build_group_val_options(group_vals, group_cols)\n",
      "  File \"/opt/homebrew/anaconda3/lib/python3.8/site-packages/dtale/dash_application/layout/layout.py\", line 1053, in build_group_val_options\n",
      "    group_vals = find_group_vals(df, group_cols)\n",
      "  File \"/opt/homebrew/anaconda3/lib/python3.8/site-packages/dtale/charts/utils.py\", line 1000, in find_group_vals\n",
      "    group_vals, _ = retrieve_chart_data(df, group_cols)\n",
      "  File \"/opt/homebrew/anaconda3/lib/python3.8/site-packages/dtale/charts/utils.py\", line 350, in retrieve_chart_data\n",
      "    all_data = pd.concat(all_data, axis=1)\n",
      "  File \"/opt/homebrew/anaconda3/lib/python3.8/site-packages/pandas/core/reshape/concat.py\", line 274, in concat\n",
      "    op = _Concatenator(\n",
      "  File \"/opt/homebrew/anaconda3/lib/python3.8/site-packages/pandas/core/reshape/concat.py\", line 331, in __init__\n",
      "    raise ValueError(\"No objects to concatenate\")\n",
      "ValueError: No objects to concatenate\n"
     ]
    },
    {
     "name": "stderr",
     "output_type": "stream",
     "text": [
      "2021-08-21 14:30:11,329 - ERROR    - Exception on /dtale/charts/_dash-update-component [POST]\n",
      "Traceback (most recent call last):\n",
      "  File \"/opt/homebrew/anaconda3/lib/python3.8/site-packages/flask/app.py\", line 2447, in wsgi_app\n",
      "    response = self.full_dispatch_request()\n",
      "  File \"/opt/homebrew/anaconda3/lib/python3.8/site-packages/flask/app.py\", line 1952, in full_dispatch_request\n",
      "    rv = self.handle_user_exception(e)\n",
      "  File \"/opt/homebrew/anaconda3/lib/python3.8/site-packages/flask/app.py\", line 1821, in handle_user_exception\n",
      "    reraise(exc_type, exc_value, tb)\n",
      "  File \"/opt/homebrew/anaconda3/lib/python3.8/site-packages/flask/_compat.py\", line 39, in reraise\n",
      "    raise value\n",
      "  File \"/opt/homebrew/anaconda3/lib/python3.8/site-packages/flask/app.py\", line 1950, in full_dispatch_request\n",
      "    rv = self.dispatch_request()\n",
      "  File \"/opt/homebrew/anaconda3/lib/python3.8/site-packages/flask/app.py\", line 1936, in dispatch_request\n",
      "    return self.view_functions[rule.endpoint](**req.view_args)\n",
      "  File \"/opt/homebrew/anaconda3/lib/python3.8/site-packages/dash/dash.py\", line 1096, in dispatch\n",
      "    response.set_data(func(*args, outputs_list=outputs_list))\n",
      "  File \"/opt/homebrew/anaconda3/lib/python3.8/site-packages/dash/dash.py\", line 1017, in add_context\n",
      "    output_value = func(*args, **kwargs)  # %% callback invoked %%\n",
      "  File \"/opt/homebrew/anaconda3/lib/python3.8/site-packages/dtale/dash_application/views.py\", line 1112, in group_values\n",
      "    group_vals = build_group_val_options(group_vals, group_cols)\n",
      "  File \"/opt/homebrew/anaconda3/lib/python3.8/site-packages/dtale/dash_application/layout/layout.py\", line 1053, in build_group_val_options\n",
      "    group_vals = find_group_vals(df, group_cols)\n",
      "  File \"/opt/homebrew/anaconda3/lib/python3.8/site-packages/dtale/charts/utils.py\", line 1000, in find_group_vals\n",
      "    group_vals, _ = retrieve_chart_data(df, group_cols)\n",
      "  File \"/opt/homebrew/anaconda3/lib/python3.8/site-packages/dtale/charts/utils.py\", line 350, in retrieve_chart_data\n",
      "    all_data = pd.concat(all_data, axis=1)\n",
      "  File \"/opt/homebrew/anaconda3/lib/python3.8/site-packages/pandas/core/reshape/concat.py\", line 274, in concat\n",
      "    op = _Concatenator(\n",
      "  File \"/opt/homebrew/anaconda3/lib/python3.8/site-packages/pandas/core/reshape/concat.py\", line 331, in __init__\n",
      "    raise ValueError(\"No objects to concatenate\")\n",
      "ValueError: No objects to concatenate\n"
     ]
    },
    {
     "name": "stdout",
     "output_type": "stream",
     "text": [
      "Exception on /dtale/charts/_dash-update-component [POST]\n",
      "Traceback (most recent call last):\n",
      "  File \"/opt/homebrew/anaconda3/lib/python3.8/site-packages/flask/app.py\", line 2447, in wsgi_app\n",
      "    response = self.full_dispatch_request()\n",
      "  File \"/opt/homebrew/anaconda3/lib/python3.8/site-packages/flask/app.py\", line 1952, in full_dispatch_request\n",
      "    rv = self.handle_user_exception(e)\n",
      "  File \"/opt/homebrew/anaconda3/lib/python3.8/site-packages/flask/app.py\", line 1821, in handle_user_exception\n",
      "    reraise(exc_type, exc_value, tb)\n",
      "  File \"/opt/homebrew/anaconda3/lib/python3.8/site-packages/flask/_compat.py\", line 39, in reraise\n",
      "    raise value\n",
      "  File \"/opt/homebrew/anaconda3/lib/python3.8/site-packages/flask/app.py\", line 1950, in full_dispatch_request\n",
      "    rv = self.dispatch_request()\n",
      "  File \"/opt/homebrew/anaconda3/lib/python3.8/site-packages/flask/app.py\", line 1936, in dispatch_request\n",
      "    return self.view_functions[rule.endpoint](**req.view_args)\n",
      "  File \"/opt/homebrew/anaconda3/lib/python3.8/site-packages/dash/dash.py\", line 1096, in dispatch\n",
      "    response.set_data(func(*args, outputs_list=outputs_list))\n",
      "  File \"/opt/homebrew/anaconda3/lib/python3.8/site-packages/dash/dash.py\", line 1017, in add_context\n",
      "    output_value = func(*args, **kwargs)  # %% callback invoked %%\n",
      "  File \"/opt/homebrew/anaconda3/lib/python3.8/site-packages/dtale/dash_application/views.py\", line 1112, in group_values\n",
      "    group_vals = build_group_val_options(group_vals, group_cols)\n",
      "  File \"/opt/homebrew/anaconda3/lib/python3.8/site-packages/dtale/dash_application/layout/layout.py\", line 1053, in build_group_val_options\n",
      "    group_vals = find_group_vals(df, group_cols)\n",
      "  File \"/opt/homebrew/anaconda3/lib/python3.8/site-packages/dtale/charts/utils.py\", line 1000, in find_group_vals\n",
      "    group_vals, _ = retrieve_chart_data(df, group_cols)\n",
      "  File \"/opt/homebrew/anaconda3/lib/python3.8/site-packages/dtale/charts/utils.py\", line 350, in retrieve_chart_data\n",
      "    all_data = pd.concat(all_data, axis=1)\n",
      "  File \"/opt/homebrew/anaconda3/lib/python3.8/site-packages/pandas/core/reshape/concat.py\", line 274, in concat\n",
      "    op = _Concatenator(\n",
      "  File \"/opt/homebrew/anaconda3/lib/python3.8/site-packages/pandas/core/reshape/concat.py\", line 331, in __init__\n",
      "    raise ValueError(\"No objects to concatenate\")\n",
      "ValueError: No objects to concatenate\n",
      "Exception on /dtale/charts/_dash-update-component [POST]\n",
      "Traceback (most recent call last):\n",
      "  File \"/opt/homebrew/anaconda3/lib/python3.8/site-packages/flask/app.py\", line 2447, in wsgi_app\n",
      "    response = self.full_dispatch_request()\n",
      "  File \"/opt/homebrew/anaconda3/lib/python3.8/site-packages/flask/app.py\", line 1952, in full_dispatch_request\n",
      "    rv = self.handle_user_exception(e)\n",
      "  File \"/opt/homebrew/anaconda3/lib/python3.8/site-packages/flask/app.py\", line 1821, in handle_user_exception\n",
      "    reraise(exc_type, exc_value, tb)\n",
      "  File \"/opt/homebrew/anaconda3/lib/python3.8/site-packages/flask/_compat.py\", line 39, in reraise\n",
      "    raise value\n",
      "  File \"/opt/homebrew/anaconda3/lib/python3.8/site-packages/flask/app.py\", line 1950, in full_dispatch_request\n",
      "    rv = self.dispatch_request()\n",
      "  File \"/opt/homebrew/anaconda3/lib/python3.8/site-packages/flask/app.py\", line 1936, in dispatch_request\n",
      "    return self.view_functions[rule.endpoint](**req.view_args)\n",
      "  File \"/opt/homebrew/anaconda3/lib/python3.8/site-packages/dash/dash.py\", line 1096, in dispatch\n",
      "    response.set_data(func(*args, outputs_list=outputs_list))\n",
      "  File \"/opt/homebrew/anaconda3/lib/python3.8/site-packages/dash/dash.py\", line 1017, in add_context\n",
      "    output_value = func(*args, **kwargs)  # %% callback invoked %%\n",
      "  File \"/opt/homebrew/anaconda3/lib/python3.8/site-packages/dtale/dash_application/views.py\", line 1112, in group_values\n",
      "    group_vals = build_group_val_options(group_vals, group_cols)\n",
      "  File \"/opt/homebrew/anaconda3/lib/python3.8/site-packages/dtale/dash_application/layout/layout.py\", line 1053, in build_group_val_options\n",
      "    group_vals = find_group_vals(df, group_cols)\n",
      "  File \"/opt/homebrew/anaconda3/lib/python3.8/site-packages/dtale/charts/utils.py\", line 1000, in find_group_vals\n",
      "    group_vals, _ = retrieve_chart_data(df, group_cols)\n",
      "  File \"/opt/homebrew/anaconda3/lib/python3.8/site-packages/dtale/charts/utils.py\", line 350, in retrieve_chart_data\n",
      "    all_data = pd.concat(all_data, axis=1)\n",
      "  File \"/opt/homebrew/anaconda3/lib/python3.8/site-packages/pandas/core/reshape/concat.py\", line 274, in concat\n",
      "    op = _Concatenator(\n",
      "  File \"/opt/homebrew/anaconda3/lib/python3.8/site-packages/pandas/core/reshape/concat.py\", line 331, in __init__\n",
      "    raise ValueError(\"No objects to concatenate\")\n",
      "ValueError: No objects to concatenate\n"
     ]
    },
    {
     "name": "stderr",
     "output_type": "stream",
     "text": [
      "2021-08-21 14:33:36,662 - ERROR    - Exception on /dtale/charts/_dash-update-component [POST]\n",
      "Traceback (most recent call last):\n",
      "  File \"/opt/homebrew/anaconda3/lib/python3.8/site-packages/flask/app.py\", line 2447, in wsgi_app\n",
      "    response = self.full_dispatch_request()\n",
      "  File \"/opt/homebrew/anaconda3/lib/python3.8/site-packages/flask/app.py\", line 1952, in full_dispatch_request\n",
      "    rv = self.handle_user_exception(e)\n",
      "  File \"/opt/homebrew/anaconda3/lib/python3.8/site-packages/flask/app.py\", line 1821, in handle_user_exception\n",
      "    reraise(exc_type, exc_value, tb)\n",
      "  File \"/opt/homebrew/anaconda3/lib/python3.8/site-packages/flask/_compat.py\", line 39, in reraise\n",
      "    raise value\n",
      "  File \"/opt/homebrew/anaconda3/lib/python3.8/site-packages/flask/app.py\", line 1950, in full_dispatch_request\n",
      "    rv = self.dispatch_request()\n",
      "  File \"/opt/homebrew/anaconda3/lib/python3.8/site-packages/flask/app.py\", line 1936, in dispatch_request\n",
      "    return self.view_functions[rule.endpoint](**req.view_args)\n",
      "  File \"/opt/homebrew/anaconda3/lib/python3.8/site-packages/dash/dash.py\", line 1096, in dispatch\n",
      "    response.set_data(func(*args, outputs_list=outputs_list))\n",
      "  File \"/opt/homebrew/anaconda3/lib/python3.8/site-packages/dash/dash.py\", line 1017, in add_context\n",
      "    output_value = func(*args, **kwargs)  # %% callback invoked %%\n",
      "  File \"/opt/homebrew/anaconda3/lib/python3.8/site-packages/dtale/dash_application/views.py\", line 1112, in group_values\n",
      "    group_vals = build_group_val_options(group_vals, group_cols)\n",
      "  File \"/opt/homebrew/anaconda3/lib/python3.8/site-packages/dtale/dash_application/layout/layout.py\", line 1053, in build_group_val_options\n",
      "    group_vals = find_group_vals(df, group_cols)\n",
      "  File \"/opt/homebrew/anaconda3/lib/python3.8/site-packages/dtale/charts/utils.py\", line 1000, in find_group_vals\n",
      "    group_vals, _ = retrieve_chart_data(df, group_cols)\n",
      "  File \"/opt/homebrew/anaconda3/lib/python3.8/site-packages/dtale/charts/utils.py\", line 350, in retrieve_chart_data\n",
      "    all_data = pd.concat(all_data, axis=1)\n",
      "  File \"/opt/homebrew/anaconda3/lib/python3.8/site-packages/pandas/core/reshape/concat.py\", line 274, in concat\n",
      "    op = _Concatenator(\n",
      "  File \"/opt/homebrew/anaconda3/lib/python3.8/site-packages/pandas/core/reshape/concat.py\", line 331, in __init__\n",
      "    raise ValueError(\"No objects to concatenate\")\n",
      "ValueError: No objects to concatenate\n"
     ]
    },
    {
     "name": "stdout",
     "output_type": "stream",
     "text": [
      "Exception on /dtale/charts/_dash-update-component [POST]\n",
      "Traceback (most recent call last):\n",
      "  File \"/opt/homebrew/anaconda3/lib/python3.8/site-packages/flask/app.py\", line 2447, in wsgi_app\n",
      "    response = self.full_dispatch_request()\n",
      "  File \"/opt/homebrew/anaconda3/lib/python3.8/site-packages/flask/app.py\", line 1952, in full_dispatch_request\n",
      "    rv = self.handle_user_exception(e)\n",
      "  File \"/opt/homebrew/anaconda3/lib/python3.8/site-packages/flask/app.py\", line 1821, in handle_user_exception\n",
      "    reraise(exc_type, exc_value, tb)\n",
      "  File \"/opt/homebrew/anaconda3/lib/python3.8/site-packages/flask/_compat.py\", line 39, in reraise\n",
      "    raise value\n",
      "  File \"/opt/homebrew/anaconda3/lib/python3.8/site-packages/flask/app.py\", line 1950, in full_dispatch_request\n",
      "    rv = self.dispatch_request()\n",
      "  File \"/opt/homebrew/anaconda3/lib/python3.8/site-packages/flask/app.py\", line 1936, in dispatch_request\n",
      "    return self.view_functions[rule.endpoint](**req.view_args)\n",
      "  File \"/opt/homebrew/anaconda3/lib/python3.8/site-packages/dash/dash.py\", line 1096, in dispatch\n",
      "    response.set_data(func(*args, outputs_list=outputs_list))\n",
      "  File \"/opt/homebrew/anaconda3/lib/python3.8/site-packages/dash/dash.py\", line 1017, in add_context\n",
      "    output_value = func(*args, **kwargs)  # %% callback invoked %%\n",
      "  File \"/opt/homebrew/anaconda3/lib/python3.8/site-packages/dtale/dash_application/views.py\", line 1112, in group_values\n",
      "    group_vals = build_group_val_options(group_vals, group_cols)\n",
      "  File \"/opt/homebrew/anaconda3/lib/python3.8/site-packages/dtale/dash_application/layout/layout.py\", line 1053, in build_group_val_options\n",
      "    group_vals = find_group_vals(df, group_cols)\n",
      "  File \"/opt/homebrew/anaconda3/lib/python3.8/site-packages/dtale/charts/utils.py\", line 1000, in find_group_vals\n",
      "    group_vals, _ = retrieve_chart_data(df, group_cols)\n",
      "  File \"/opt/homebrew/anaconda3/lib/python3.8/site-packages/dtale/charts/utils.py\", line 350, in retrieve_chart_data\n",
      "    all_data = pd.concat(all_data, axis=1)\n",
      "  File \"/opt/homebrew/anaconda3/lib/python3.8/site-packages/pandas/core/reshape/concat.py\", line 274, in concat\n",
      "    op = _Concatenator(\n",
      "  File \"/opt/homebrew/anaconda3/lib/python3.8/site-packages/pandas/core/reshape/concat.py\", line 331, in __init__\n",
      "    raise ValueError(\"No objects to concatenate\")\n",
      "ValueError: No objects to concatenate\n",
      "Exception on /dtale/charts/_dash-update-component [POST]\n",
      "Traceback (most recent call last):\n",
      "  File \"/opt/homebrew/anaconda3/lib/python3.8/site-packages/flask/app.py\", line 2447, in wsgi_app\n",
      "    response = self.full_dispatch_request()\n",
      "  File \"/opt/homebrew/anaconda3/lib/python3.8/site-packages/flask/app.py\", line 1952, in full_dispatch_request\n",
      "    rv = self.handle_user_exception(e)\n",
      "  File \"/opt/homebrew/anaconda3/lib/python3.8/site-packages/flask/app.py\", line 1821, in handle_user_exception\n",
      "    reraise(exc_type, exc_value, tb)\n",
      "  File \"/opt/homebrew/anaconda3/lib/python3.8/site-packages/flask/_compat.py\", line 39, in reraise\n",
      "    raise value\n",
      "  File \"/opt/homebrew/anaconda3/lib/python3.8/site-packages/flask/app.py\", line 1950, in full_dispatch_request\n",
      "    rv = self.dispatch_request()\n",
      "  File \"/opt/homebrew/anaconda3/lib/python3.8/site-packages/flask/app.py\", line 1936, in dispatch_request\n",
      "    return self.view_functions[rule.endpoint](**req.view_args)\n",
      "  File \"/opt/homebrew/anaconda3/lib/python3.8/site-packages/dash/dash.py\", line 1096, in dispatch\n",
      "    response.set_data(func(*args, outputs_list=outputs_list))\n",
      "  File \"/opt/homebrew/anaconda3/lib/python3.8/site-packages/dash/dash.py\", line 1017, in add_context\n",
      "    output_value = func(*args, **kwargs)  # %% callback invoked %%\n",
      "  File \"/opt/homebrew/anaconda3/lib/python3.8/site-packages/dtale/dash_application/views.py\", line 1112, in group_values\n",
      "    group_vals = build_group_val_options(group_vals, group_cols)\n",
      "  File \"/opt/homebrew/anaconda3/lib/python3.8/site-packages/dtale/dash_application/layout/layout.py\", line 1053, in build_group_val_options\n",
      "    group_vals = find_group_vals(df, group_cols)\n",
      "  File \"/opt/homebrew/anaconda3/lib/python3.8/site-packages/dtale/charts/utils.py\", line 1000, in find_group_vals\n",
      "    group_vals, _ = retrieve_chart_data(df, group_cols)\n",
      "  File \"/opt/homebrew/anaconda3/lib/python3.8/site-packages/dtale/charts/utils.py\", line 350, in retrieve_chart_data\n",
      "    all_data = pd.concat(all_data, axis=1)\n",
      "  File \"/opt/homebrew/anaconda3/lib/python3.8/site-packages/pandas/core/reshape/concat.py\", line 274, in concat\n",
      "    op = _Concatenator(\n",
      "  File \"/opt/homebrew/anaconda3/lib/python3.8/site-packages/pandas/core/reshape/concat.py\", line 331, in __init__\n",
      "    raise ValueError(\"No objects to concatenate\")\n",
      "ValueError: No objects to concatenate\n"
     ]
    },
    {
     "name": "stderr",
     "output_type": "stream",
     "text": [
      "2021-08-21 14:34:07,523 - ERROR    - Exception on /dtale/charts/_dash-update-component [POST]\n",
      "Traceback (most recent call last):\n",
      "  File \"/opt/homebrew/anaconda3/lib/python3.8/site-packages/flask/app.py\", line 2447, in wsgi_app\n",
      "    response = self.full_dispatch_request()\n",
      "  File \"/opt/homebrew/anaconda3/lib/python3.8/site-packages/flask/app.py\", line 1952, in full_dispatch_request\n",
      "    rv = self.handle_user_exception(e)\n",
      "  File \"/opt/homebrew/anaconda3/lib/python3.8/site-packages/flask/app.py\", line 1821, in handle_user_exception\n",
      "    reraise(exc_type, exc_value, tb)\n",
      "  File \"/opt/homebrew/anaconda3/lib/python3.8/site-packages/flask/_compat.py\", line 39, in reraise\n",
      "    raise value\n",
      "  File \"/opt/homebrew/anaconda3/lib/python3.8/site-packages/flask/app.py\", line 1950, in full_dispatch_request\n",
      "    rv = self.dispatch_request()\n",
      "  File \"/opt/homebrew/anaconda3/lib/python3.8/site-packages/flask/app.py\", line 1936, in dispatch_request\n",
      "    return self.view_functions[rule.endpoint](**req.view_args)\n",
      "  File \"/opt/homebrew/anaconda3/lib/python3.8/site-packages/dash/dash.py\", line 1096, in dispatch\n",
      "    response.set_data(func(*args, outputs_list=outputs_list))\n",
      "  File \"/opt/homebrew/anaconda3/lib/python3.8/site-packages/dash/dash.py\", line 1017, in add_context\n",
      "    output_value = func(*args, **kwargs)  # %% callback invoked %%\n",
      "  File \"/opt/homebrew/anaconda3/lib/python3.8/site-packages/dtale/dash_application/views.py\", line 1112, in group_values\n",
      "    group_vals = build_group_val_options(group_vals, group_cols)\n",
      "  File \"/opt/homebrew/anaconda3/lib/python3.8/site-packages/dtale/dash_application/layout/layout.py\", line 1053, in build_group_val_options\n",
      "    group_vals = find_group_vals(df, group_cols)\n",
      "  File \"/opt/homebrew/anaconda3/lib/python3.8/site-packages/dtale/charts/utils.py\", line 1000, in find_group_vals\n",
      "    group_vals, _ = retrieve_chart_data(df, group_cols)\n",
      "  File \"/opt/homebrew/anaconda3/lib/python3.8/site-packages/dtale/charts/utils.py\", line 350, in retrieve_chart_data\n",
      "    all_data = pd.concat(all_data, axis=1)\n",
      "  File \"/opt/homebrew/anaconda3/lib/python3.8/site-packages/pandas/core/reshape/concat.py\", line 274, in concat\n",
      "    op = _Concatenator(\n",
      "  File \"/opt/homebrew/anaconda3/lib/python3.8/site-packages/pandas/core/reshape/concat.py\", line 331, in __init__\n",
      "    raise ValueError(\"No objects to concatenate\")\n",
      "ValueError: No objects to concatenate\n"
     ]
    },
    {
     "name": "stdout",
     "output_type": "stream",
     "text": [
      "Exception on /dtale/charts/_dash-update-component [POST]\n",
      "Traceback (most recent call last):\n",
      "  File \"/opt/homebrew/anaconda3/lib/python3.8/site-packages/flask/app.py\", line 2447, in wsgi_app\n",
      "    response = self.full_dispatch_request()\n",
      "  File \"/opt/homebrew/anaconda3/lib/python3.8/site-packages/flask/app.py\", line 1952, in full_dispatch_request\n",
      "    rv = self.handle_user_exception(e)\n",
      "  File \"/opt/homebrew/anaconda3/lib/python3.8/site-packages/flask/app.py\", line 1821, in handle_user_exception\n",
      "    reraise(exc_type, exc_value, tb)\n",
      "  File \"/opt/homebrew/anaconda3/lib/python3.8/site-packages/flask/_compat.py\", line 39, in reraise\n",
      "    raise value\n",
      "  File \"/opt/homebrew/anaconda3/lib/python3.8/site-packages/flask/app.py\", line 1950, in full_dispatch_request\n",
      "    rv = self.dispatch_request()\n",
      "  File \"/opt/homebrew/anaconda3/lib/python3.8/site-packages/flask/app.py\", line 1936, in dispatch_request\n",
      "    return self.view_functions[rule.endpoint](**req.view_args)\n",
      "  File \"/opt/homebrew/anaconda3/lib/python3.8/site-packages/dash/dash.py\", line 1096, in dispatch\n",
      "    response.set_data(func(*args, outputs_list=outputs_list))\n",
      "  File \"/opt/homebrew/anaconda3/lib/python3.8/site-packages/dash/dash.py\", line 1017, in add_context\n",
      "    output_value = func(*args, **kwargs)  # %% callback invoked %%\n",
      "  File \"/opt/homebrew/anaconda3/lib/python3.8/site-packages/dtale/dash_application/views.py\", line 1112, in group_values\n",
      "    group_vals = build_group_val_options(group_vals, group_cols)\n",
      "  File \"/opt/homebrew/anaconda3/lib/python3.8/site-packages/dtale/dash_application/layout/layout.py\", line 1053, in build_group_val_options\n",
      "    group_vals = find_group_vals(df, group_cols)\n",
      "  File \"/opt/homebrew/anaconda3/lib/python3.8/site-packages/dtale/charts/utils.py\", line 1000, in find_group_vals\n",
      "    group_vals, _ = retrieve_chart_data(df, group_cols)\n",
      "  File \"/opt/homebrew/anaconda3/lib/python3.8/site-packages/dtale/charts/utils.py\", line 350, in retrieve_chart_data\n",
      "    all_data = pd.concat(all_data, axis=1)\n",
      "  File \"/opt/homebrew/anaconda3/lib/python3.8/site-packages/pandas/core/reshape/concat.py\", line 274, in concat\n",
      "    op = _Concatenator(\n",
      "  File \"/opt/homebrew/anaconda3/lib/python3.8/site-packages/pandas/core/reshape/concat.py\", line 331, in __init__\n",
      "    raise ValueError(\"No objects to concatenate\")\n",
      "ValueError: No objects to concatenate\n",
      "Exception on /dtale/charts/_dash-update-component [POST]\n",
      "Traceback (most recent call last):\n",
      "  File \"/opt/homebrew/anaconda3/lib/python3.8/site-packages/flask/app.py\", line 2447, in wsgi_app\n",
      "    response = self.full_dispatch_request()\n",
      "  File \"/opt/homebrew/anaconda3/lib/python3.8/site-packages/flask/app.py\", line 1952, in full_dispatch_request\n",
      "    rv = self.handle_user_exception(e)\n",
      "  File \"/opt/homebrew/anaconda3/lib/python3.8/site-packages/flask/app.py\", line 1821, in handle_user_exception\n",
      "    reraise(exc_type, exc_value, tb)\n",
      "  File \"/opt/homebrew/anaconda3/lib/python3.8/site-packages/flask/_compat.py\", line 39, in reraise\n",
      "    raise value\n",
      "  File \"/opt/homebrew/anaconda3/lib/python3.8/site-packages/flask/app.py\", line 1950, in full_dispatch_request\n",
      "    rv = self.dispatch_request()\n",
      "  File \"/opt/homebrew/anaconda3/lib/python3.8/site-packages/flask/app.py\", line 1936, in dispatch_request\n",
      "    return self.view_functions[rule.endpoint](**req.view_args)\n",
      "  File \"/opt/homebrew/anaconda3/lib/python3.8/site-packages/dash/dash.py\", line 1096, in dispatch\n",
      "    response.set_data(func(*args, outputs_list=outputs_list))\n",
      "  File \"/opt/homebrew/anaconda3/lib/python3.8/site-packages/dash/dash.py\", line 1017, in add_context\n",
      "    output_value = func(*args, **kwargs)  # %% callback invoked %%\n",
      "  File \"/opt/homebrew/anaconda3/lib/python3.8/site-packages/dtale/dash_application/views.py\", line 1112, in group_values\n",
      "    group_vals = build_group_val_options(group_vals, group_cols)\n",
      "  File \"/opt/homebrew/anaconda3/lib/python3.8/site-packages/dtale/dash_application/layout/layout.py\", line 1053, in build_group_val_options\n",
      "    group_vals = find_group_vals(df, group_cols)\n",
      "  File \"/opt/homebrew/anaconda3/lib/python3.8/site-packages/dtale/charts/utils.py\", line 1000, in find_group_vals\n",
      "    group_vals, _ = retrieve_chart_data(df, group_cols)\n",
      "  File \"/opt/homebrew/anaconda3/lib/python3.8/site-packages/dtale/charts/utils.py\", line 350, in retrieve_chart_data\n",
      "    all_data = pd.concat(all_data, axis=1)\n",
      "  File \"/opt/homebrew/anaconda3/lib/python3.8/site-packages/pandas/core/reshape/concat.py\", line 274, in concat\n",
      "    op = _Concatenator(\n",
      "  File \"/opt/homebrew/anaconda3/lib/python3.8/site-packages/pandas/core/reshape/concat.py\", line 331, in __init__\n",
      "    raise ValueError(\"No objects to concatenate\")\n",
      "ValueError: No objects to concatenate\n"
     ]
    },
    {
     "name": "stderr",
     "output_type": "stream",
     "text": [
      "2021-08-21 14:34:47,156 - ERROR    - Exception on /dtale/charts/_dash-update-component [POST]\n",
      "Traceback (most recent call last):\n",
      "  File \"/opt/homebrew/anaconda3/lib/python3.8/site-packages/flask/app.py\", line 2447, in wsgi_app\n",
      "    response = self.full_dispatch_request()\n",
      "  File \"/opt/homebrew/anaconda3/lib/python3.8/site-packages/flask/app.py\", line 1952, in full_dispatch_request\n",
      "    rv = self.handle_user_exception(e)\n",
      "  File \"/opt/homebrew/anaconda3/lib/python3.8/site-packages/flask/app.py\", line 1821, in handle_user_exception\n",
      "    reraise(exc_type, exc_value, tb)\n",
      "  File \"/opt/homebrew/anaconda3/lib/python3.8/site-packages/flask/_compat.py\", line 39, in reraise\n",
      "    raise value\n",
      "  File \"/opt/homebrew/anaconda3/lib/python3.8/site-packages/flask/app.py\", line 1950, in full_dispatch_request\n",
      "    rv = self.dispatch_request()\n",
      "  File \"/opt/homebrew/anaconda3/lib/python3.8/site-packages/flask/app.py\", line 1936, in dispatch_request\n",
      "    return self.view_functions[rule.endpoint](**req.view_args)\n",
      "  File \"/opt/homebrew/anaconda3/lib/python3.8/site-packages/dash/dash.py\", line 1096, in dispatch\n",
      "    response.set_data(func(*args, outputs_list=outputs_list))\n",
      "  File \"/opt/homebrew/anaconda3/lib/python3.8/site-packages/dash/dash.py\", line 1017, in add_context\n",
      "    output_value = func(*args, **kwargs)  # %% callback invoked %%\n",
      "  File \"/opt/homebrew/anaconda3/lib/python3.8/site-packages/dtale/dash_application/views.py\", line 1112, in group_values\n",
      "    group_vals = build_group_val_options(group_vals, group_cols)\n",
      "  File \"/opt/homebrew/anaconda3/lib/python3.8/site-packages/dtale/dash_application/layout/layout.py\", line 1053, in build_group_val_options\n",
      "    group_vals = find_group_vals(df, group_cols)\n",
      "  File \"/opt/homebrew/anaconda3/lib/python3.8/site-packages/dtale/charts/utils.py\", line 1000, in find_group_vals\n",
      "    group_vals, _ = retrieve_chart_data(df, group_cols)\n",
      "  File \"/opt/homebrew/anaconda3/lib/python3.8/site-packages/dtale/charts/utils.py\", line 350, in retrieve_chart_data\n",
      "    all_data = pd.concat(all_data, axis=1)\n",
      "  File \"/opt/homebrew/anaconda3/lib/python3.8/site-packages/pandas/core/reshape/concat.py\", line 274, in concat\n",
      "    op = _Concatenator(\n",
      "  File \"/opt/homebrew/anaconda3/lib/python3.8/site-packages/pandas/core/reshape/concat.py\", line 331, in __init__\n",
      "    raise ValueError(\"No objects to concatenate\")\n",
      "ValueError: No objects to concatenate\n"
     ]
    },
    {
     "name": "stdout",
     "output_type": "stream",
     "text": [
      "Exception on /dtale/charts/_dash-update-component [POST]\n",
      "Traceback (most recent call last):\n",
      "  File \"/opt/homebrew/anaconda3/lib/python3.8/site-packages/flask/app.py\", line 2447, in wsgi_app\n",
      "    response = self.full_dispatch_request()\n",
      "  File \"/opt/homebrew/anaconda3/lib/python3.8/site-packages/flask/app.py\", line 1952, in full_dispatch_request\n",
      "    rv = self.handle_user_exception(e)\n",
      "  File \"/opt/homebrew/anaconda3/lib/python3.8/site-packages/flask/app.py\", line 1821, in handle_user_exception\n",
      "    reraise(exc_type, exc_value, tb)\n",
      "  File \"/opt/homebrew/anaconda3/lib/python3.8/site-packages/flask/_compat.py\", line 39, in reraise\n",
      "    raise value\n",
      "  File \"/opt/homebrew/anaconda3/lib/python3.8/site-packages/flask/app.py\", line 1950, in full_dispatch_request\n",
      "    rv = self.dispatch_request()\n",
      "  File \"/opt/homebrew/anaconda3/lib/python3.8/site-packages/flask/app.py\", line 1936, in dispatch_request\n",
      "    return self.view_functions[rule.endpoint](**req.view_args)\n",
      "  File \"/opt/homebrew/anaconda3/lib/python3.8/site-packages/dash/dash.py\", line 1096, in dispatch\n",
      "    response.set_data(func(*args, outputs_list=outputs_list))\n",
      "  File \"/opt/homebrew/anaconda3/lib/python3.8/site-packages/dash/dash.py\", line 1017, in add_context\n",
      "    output_value = func(*args, **kwargs)  # %% callback invoked %%\n",
      "  File \"/opt/homebrew/anaconda3/lib/python3.8/site-packages/dtale/dash_application/views.py\", line 1112, in group_values\n",
      "    group_vals = build_group_val_options(group_vals, group_cols)\n",
      "  File \"/opt/homebrew/anaconda3/lib/python3.8/site-packages/dtale/dash_application/layout/layout.py\", line 1053, in build_group_val_options\n",
      "    group_vals = find_group_vals(df, group_cols)\n",
      "  File \"/opt/homebrew/anaconda3/lib/python3.8/site-packages/dtale/charts/utils.py\", line 1000, in find_group_vals\n",
      "    group_vals, _ = retrieve_chart_data(df, group_cols)\n",
      "  File \"/opt/homebrew/anaconda3/lib/python3.8/site-packages/dtale/charts/utils.py\", line 350, in retrieve_chart_data\n",
      "    all_data = pd.concat(all_data, axis=1)\n",
      "  File \"/opt/homebrew/anaconda3/lib/python3.8/site-packages/pandas/core/reshape/concat.py\", line 274, in concat\n",
      "    op = _Concatenator(\n",
      "  File \"/opt/homebrew/anaconda3/lib/python3.8/site-packages/pandas/core/reshape/concat.py\", line 331, in __init__\n",
      "    raise ValueError(\"No objects to concatenate\")\n",
      "ValueError: No objects to concatenate\n",
      "Exception on /dtale/charts/_dash-update-component [POST]\n",
      "Traceback (most recent call last):\n",
      "  File \"/opt/homebrew/anaconda3/lib/python3.8/site-packages/flask/app.py\", line 2447, in wsgi_app\n",
      "    response = self.full_dispatch_request()\n",
      "  File \"/opt/homebrew/anaconda3/lib/python3.8/site-packages/flask/app.py\", line 1952, in full_dispatch_request\n",
      "    rv = self.handle_user_exception(e)\n",
      "  File \"/opt/homebrew/anaconda3/lib/python3.8/site-packages/flask/app.py\", line 1821, in handle_user_exception\n",
      "    reraise(exc_type, exc_value, tb)\n",
      "  File \"/opt/homebrew/anaconda3/lib/python3.8/site-packages/flask/_compat.py\", line 39, in reraise\n",
      "    raise value\n",
      "  File \"/opt/homebrew/anaconda3/lib/python3.8/site-packages/flask/app.py\", line 1950, in full_dispatch_request\n",
      "    rv = self.dispatch_request()\n",
      "  File \"/opt/homebrew/anaconda3/lib/python3.8/site-packages/flask/app.py\", line 1936, in dispatch_request\n",
      "    return self.view_functions[rule.endpoint](**req.view_args)\n",
      "  File \"/opt/homebrew/anaconda3/lib/python3.8/site-packages/dash/dash.py\", line 1096, in dispatch\n",
      "    response.set_data(func(*args, outputs_list=outputs_list))\n",
      "  File \"/opt/homebrew/anaconda3/lib/python3.8/site-packages/dash/dash.py\", line 1017, in add_context\n",
      "    output_value = func(*args, **kwargs)  # %% callback invoked %%\n",
      "  File \"/opt/homebrew/anaconda3/lib/python3.8/site-packages/dtale/dash_application/views.py\", line 1112, in group_values\n",
      "    group_vals = build_group_val_options(group_vals, group_cols)\n",
      "  File \"/opt/homebrew/anaconda3/lib/python3.8/site-packages/dtale/dash_application/layout/layout.py\", line 1053, in build_group_val_options\n",
      "    group_vals = find_group_vals(df, group_cols)\n",
      "  File \"/opt/homebrew/anaconda3/lib/python3.8/site-packages/dtale/charts/utils.py\", line 1000, in find_group_vals\n",
      "    group_vals, _ = retrieve_chart_data(df, group_cols)\n",
      "  File \"/opt/homebrew/anaconda3/lib/python3.8/site-packages/dtale/charts/utils.py\", line 350, in retrieve_chart_data\n",
      "    all_data = pd.concat(all_data, axis=1)\n",
      "  File \"/opt/homebrew/anaconda3/lib/python3.8/site-packages/pandas/core/reshape/concat.py\", line 274, in concat\n",
      "    op = _Concatenator(\n",
      "  File \"/opt/homebrew/anaconda3/lib/python3.8/site-packages/pandas/core/reshape/concat.py\", line 331, in __init__\n",
      "    raise ValueError(\"No objects to concatenate\")\n",
      "ValueError: No objects to concatenate\n"
     ]
    },
    {
     "name": "stderr",
     "output_type": "stream",
     "text": [
      "2021-08-21 14:38:08,198 - ERROR    - Exception on /dtale/charts/_dash-update-component [POST]\n",
      "Traceback (most recent call last):\n",
      "  File \"/opt/homebrew/anaconda3/lib/python3.8/site-packages/flask/app.py\", line 2447, in wsgi_app\n",
      "    response = self.full_dispatch_request()\n",
      "  File \"/opt/homebrew/anaconda3/lib/python3.8/site-packages/flask/app.py\", line 1952, in full_dispatch_request\n",
      "    rv = self.handle_user_exception(e)\n",
      "  File \"/opt/homebrew/anaconda3/lib/python3.8/site-packages/flask/app.py\", line 1821, in handle_user_exception\n",
      "    reraise(exc_type, exc_value, tb)\n",
      "  File \"/opt/homebrew/anaconda3/lib/python3.8/site-packages/flask/_compat.py\", line 39, in reraise\n",
      "    raise value\n",
      "  File \"/opt/homebrew/anaconda3/lib/python3.8/site-packages/flask/app.py\", line 1950, in full_dispatch_request\n",
      "    rv = self.dispatch_request()\n",
      "  File \"/opt/homebrew/anaconda3/lib/python3.8/site-packages/flask/app.py\", line 1936, in dispatch_request\n",
      "    return self.view_functions[rule.endpoint](**req.view_args)\n",
      "  File \"/opt/homebrew/anaconda3/lib/python3.8/site-packages/dash/dash.py\", line 1096, in dispatch\n",
      "    response.set_data(func(*args, outputs_list=outputs_list))\n",
      "  File \"/opt/homebrew/anaconda3/lib/python3.8/site-packages/dash/dash.py\", line 1017, in add_context\n",
      "    output_value = func(*args, **kwargs)  # %% callback invoked %%\n",
      "  File \"/opt/homebrew/anaconda3/lib/python3.8/site-packages/dtale/dash_application/views.py\", line 1112, in group_values\n",
      "    group_vals = build_group_val_options(group_vals, group_cols)\n",
      "  File \"/opt/homebrew/anaconda3/lib/python3.8/site-packages/dtale/dash_application/layout/layout.py\", line 1053, in build_group_val_options\n",
      "    group_vals = find_group_vals(df, group_cols)\n",
      "  File \"/opt/homebrew/anaconda3/lib/python3.8/site-packages/dtale/charts/utils.py\", line 1000, in find_group_vals\n",
      "    group_vals, _ = retrieve_chart_data(df, group_cols)\n",
      "  File \"/opt/homebrew/anaconda3/lib/python3.8/site-packages/dtale/charts/utils.py\", line 350, in retrieve_chart_data\n",
      "    all_data = pd.concat(all_data, axis=1)\n",
      "  File \"/opt/homebrew/anaconda3/lib/python3.8/site-packages/pandas/core/reshape/concat.py\", line 274, in concat\n",
      "    op = _Concatenator(\n",
      "  File \"/opt/homebrew/anaconda3/lib/python3.8/site-packages/pandas/core/reshape/concat.py\", line 331, in __init__\n",
      "    raise ValueError(\"No objects to concatenate\")\n",
      "ValueError: No objects to concatenate\n"
     ]
    },
    {
     "name": "stdout",
     "output_type": "stream",
     "text": [
      "Executing shutdown due to inactivity...\n",
      "Executing shutdown due to inactivity...\n"
     ]
    },
    {
     "name": "stderr",
     "output_type": "stream",
     "text": [
      "2021-08-21 15:42:05,133 - INFO     - Executing shutdown due to inactivity...\n"
     ]
    },
    {
     "name": "stdout",
     "output_type": "stream",
     "text": [
      "Executing shutdown...\n",
      "Executing shutdown...\n"
     ]
    },
    {
     "name": "stderr",
     "output_type": "stream",
     "text": [
      "2021-08-21 15:42:05,199 - INFO     - Executing shutdown...\n"
     ]
    }
   ],
   "source": [
    "data = pd.read_excel('Clean_data.xlsx')\n",
    "pd.set_option('display.max_columns',None)\n",
    "pd.set_option(\"display.max_rows\", None)\n",
    "\n",
    "\n",
    "d = dtale.show(data)\n",
    "d.open_browser()"
   ]
  },
  {
   "cell_type": "code",
   "execution_count": null,
   "metadata": {},
   "outputs": [],
   "source": []
  }
 ],
 "metadata": {
  "kernelspec": {
   "display_name": "Python 3",
   "language": "python",
   "name": "python3"
  },
  "language_info": {
   "codemirror_mode": {
    "name": "ipython",
    "version": 3
   },
   "file_extension": ".py",
   "mimetype": "text/x-python",
   "name": "python",
   "nbconvert_exporter": "python",
   "pygments_lexer": "ipython3",
   "version": "3.8.2"
  }
 },
 "nbformat": 4,
 "nbformat_minor": 4
}
